<?xml version="1.0"?>
<robot name="marty">
  <link name="base_link">
    <visual>
      <geometry>
        <mesh filename="package://marty_description/meshes/base.stl"/>
      </geometry>
      <origin rpy="1.57075 0 1.57075" xyz="-0.05 -0.0635 0"/>
      <material name="blue">
        <color rgba="0.07 0.52 .625 1"/>
      </material>
    </visual>
    <collision>
      <geometry>
        <mesh filename="package://marty_description/meshes/base.stl"/>
      </geometry>
      <origin rpy="1.57075 0 1.57075" xyz="-0.05 -0.0635 0"/>
      <material name="blue">
        <color rgba="0.07 0.52 .625 1"/>
      </material>
    </collision>
  </link>
  <joint name="face_joint" type="revolute">
    <origin rpy="0 0 0" xyz="-0.047 0.0015 0.075"/>
    <axis xyz="0 1 0"/>
    <limit effort="1000.0" lower="-4.5" upper="0" velocity="0.5"/>
    <parent link="base_link"/>
    <child link="face"/>
  </joint>
  <link name="face">
    <visual>
      <geometry>
        <mesh filename="package://marty_description/meshes/face.stl"/>
      </geometry>
      <material name="blue"/>
      <origin rpy="1.57075 0 1.57075" xyz="-0.003 -0.0655 -0.075"/>
    </visual>
    <collision>
      <geometry>
        <mesh filename="package://marty_description/meshes/face.stl"/>
      </geometry>
      <material name="blue"/>
      <origin rpy="1.57075 0 1.57075" xyz="-0.003 -0.0655 -0.075"/>
    </collision>
  </link>
  <joint name="rpi_camera_mount_joint" type="fixed">
    <origin rpy="0 0 0" xyz="0.012 0 0.002"/>
    <parent link="base_link"/>
    <child link="rpi_camera_mount"/>
  </joint>
  <link name="rpi_camera_mount">
    <visual>
      <geometry>
        <mesh filename="package://marty_description/meshes/rpiCameraMount.stl"/>
      </geometry>
      <material name="blue"/>
      <origin rpy="1.57075 0 0" xyz="0 0.0125 0"/>
    </visual>
    <collision>
      <geometry>
        <mesh filename="package://marty_description/meshes/rpiCameraMount.stl"/>
      </geometry>
      <material name="blue"/>
      <origin rpy="1.57075 0 0" xyz="0 0.0125 0"/>
    </collision>
  </link>
  <joint name="left_side_panel_joint" type="fixed">
    <origin rpy="0 0 0" xyz="-0.006 0.0575 0.0375"/>
    <parent link="base_link"/>
    <child link="left_side_panel"/>
  </joint>
  <link name="left_side_panel">
    <visual>
      <geometry>
        <mesh filename="package://marty_description/meshes/sidePanel.stl"/>
      </geometry>
      <material name="yellow">
        <color rgba=".8 .8 0 1"/>
      </material>
      <origin rpy="1.57075 0 -1.57075" xyz="0.0437 0.005 -0.0375"/>
    </visual>
    <collision>
      <geometry>
        <mesh filename="package://marty_description/meshes/sidePanel.stl"/>
      </geometry>
      <material name="yellow">
        <color rgba=".8 .8 0 1"/>
      </material>
      <origin rpy="1.57075 0 -1.57075" xyz="0.0437 0.005 -0.0375"/>
    </collision>
  </link>
  <joint name="left_arm_servo_gear_joint" type="revolute">
    <origin rpy="-1.57 0.085 0" xyz="0 0.002 0.014"/>
    <axis xyz="0 0 1"/>
    <limit effort="1000.0" lower="-3.1415" upper="3.1415" velocity="0.5"/>
    <parent link="left_side_panel"/>
    <child link="left_arm_servo_gear"/>
  </joint>
  <link name="left_arm_servo_gear">
    <visual>
      <geometry>
        <mesh filename="package://marty_description/meshes/armServoGear.stl"/>
      </geometry>
      <material name="yellow"/>
      <origin rpy="0 1.57 0" xyz="-0.02 -0.02 0.003"/>
    </visual>
    <collision>
      <geometry>
        <mesh filename="package://marty_description/meshes/armServoGear.stl"/>
      </geometry>
      <material name="yellow"/>
      <origin rpy="0 1.57 0" xyz="-0.02 -0.02 0.003"/>
    </collision>
  </link>
  <joint name="left_arm_gear_joint" type="revolute">
    <origin rpy="-1.57075 0 0" xyz="0 0 -0.021"/>
    <mimic joint="left_arm_servo_gear_joint" multiplier="-1.1875" offset="0"/>
    <axis xyz="0 0 1"/>
    <limit effort="1000.0" lower="-3.1415" upper="3.1415" velocity="0.5"/>
    <parent link="left_side_panel"/>
    <child link="left_arm_gear"/>
  </joint>
  <link name="left_arm_gear">
    <visual>
      <geometry>
        <mesh filename="package://marty_description/meshes/armGear.stl"/>
      </geometry>
      <material name="yellow"/>
      <origin rpy="0 0 0" xyz="-0.017 -0.017 -0.002"/>
    </visual>
    <collision>
      <geometry>
        <mesh filename="package://marty_description/meshes/armGear.stl"/>
      </geometry>
      <material name="yellow"/>
      <origin rpy="0 0 0" xyz="-0.017 -0.017 -0.002"/>
    </collision>
  </link>
  <joint name="left_arm_joint" type="fixed">
    <origin rpy="0 0 0" xyz="0 0 0"/>
    <parent link="left_arm_gear"/>
    <child link="left_arm"/>
  </joint>
  <link name="left_arm">
    <visual>
      <geometry>
        <mesh filename="package://marty_description/meshes/arm.stl"/>
      </geometry>
      <material name="yellow"/>
      <origin rpy="-0.35 0 3.1415" xyz="0.0125 0.0585 0.02"/>
    </visual>
    <collision>
      <geometry>
        <mesh filename="package://marty_description/meshes/arm.stl"/>
      </geometry>
      <material name="yellow"/>
      <origin rpy="-0.35 0 3.1415" xyz="0.0125 0.0585 0.02"/>
    </collision>
  </link>
  <joint name="left_hand_joint" type="fixed">
    <origin rpy="0.35 0 0" xyz="0 0.058 0.03"/>
    <parent link="left_arm"/>
    <child link="left_hand"/>
  </joint>
  <link name="left_hand">
    <visual>
      <geometry>
        <mesh filename="package://marty_description/meshes/hand.stl"/>
      </geometry>
      <material name="yellow"/>
      <origin rpy="0 0 3.1415" xyz="0.013125 0.0189 -0.006"/>
    </visual>
    <collision>
      <geometry>
        <mesh filename="package://marty_description/meshes/hand.stl"/>
      </geometry>
      <material name="yellow"/>
      <origin rpy="0 0 3.1415" xyz="0.013125 0.0189 -0.006"/>
    </collision>
  </link>
  <joint name="right_side_panel_joint" type="fixed">
    <origin rpy="0 0 0" xyz="-0.006 -0.055 0.0375"/>
    <parent link="base_link"/>
    <child link="right_side_panel"/>
  </joint>
  <link name="right_side_panel">
    <visual>
      <geometry>
        <mesh filename="package://marty_description/meshes/sidePanel.stl"/>
      </geometry>
      <material name="yellow">
        <color rgba=".8 .8 0 1"/>
      </material>
      <origin rpy="1.57075 0 1.57075" xyz="-0.0437 -0.0075 -0.0375"/>
    </visual>
    <collision>
      <geometry>
        <mesh filename="package://marty_description/meshes/sidePanel.stl"/>
      </geometry>
      <material name="yellow">
        <color rgba=".8 .8 0 1"/>
      </material>
      <origin rpy="1.57075 0 1.57075" xyz="-0.0437 -0.0075 -0.0375"/>
    </collision>
  </link>
  <joint name="right_arm_servo_gear_joint" type="revolute">
    <origin rpy="1.57075 -3.055 0" xyz="0 -0.0035 0.014"/>
    <axis xyz="0 0 1"/>
    <limit effort="1000.0" lower="-3.1415" upper="3.1415" velocity="0.5"/>
    <parent link="right_side_panel"/>
    <child link="right_arm_servo_gear"/>
  </joint>
  <link name="right_arm_servo_gear">
    <visual>
      <geometry>
        <mesh filename="package://marty_description/meshes/armServoGear.stl"/>
      </geometry>
      <material name="yellow"/>
      <origin rpy="0 1.57075 0" xyz="-0.02 -0.02 0.003"/>
    </visual>
    <collision>
      <geometry>
        <mesh filename="package://marty_description/meshes/armServoGear.stl"/>
      </geometry>
      <material name="yellow"/>
      <origin rpy="0 1.57075 0" xyz="-0.02 -0.02 0.003"/>
    </collision>
  </link>
  <joint name="right_arm_gear_joint" type="revolute">
    <mimic joint="right_arm_servo_gear_joint" multiplier="-1.1875" offset="0"/>
    <origin rpy="1.57075 -3.1415 0" xyz="0 -0.0015 -0.021"/>
    <axis xyz="0 0 1"/>
    <limit effort="1000.0" lower="-3.1415" upper="3.1415" velocity="0.5"/>
    <parent link="right_side_panel"/>
    <child link="right_arm_gear"/>
  </joint>
  <link name="right_arm_gear">
    <visual>
      <geometry>
        <mesh filename="package://marty_description/meshes/armGear.stl"/>
      </geometry>
      <material name="yellow"/>
      <origin rpy="0 0 0" xyz="-0.017 -0.017 -0.002"/>
    </visual>
    <collision>
      <geometry>
        <mesh filename="package://marty_description/meshes/armGear.stl"/>
      </geometry>
      <material name="yellow"/>
      <origin rpy="0 0 0" xyz="-0.017 -0.017 -0.002"/>
    </collision>
  </link>
  <joint name="right_arm_joint" type="fixed">
    <origin rpy="0 0 0" xyz="0 0 0"/>
    <parent link="right_arm_gear"/>
    <child link="right_arm"/>
  </joint>
  <link name="right_arm">
    <visual>
      <geometry>
        <mesh filename="package://marty_description/meshes/arm.stl"/>
      </geometry>
      <material name="yellow"/>
      <origin rpy="-0.35 0 3.1415" xyz="0.0125 0.0585 0.02"/>
    </visual>
    <collision>
      <geometry>
        <mesh filename="package://marty_description/meshes/arm.stl"/>
      </geometry>
      <material name="yellow"/>
      <origin rpy="-0.35 0 3.1415" xyz="0.0125 0.0585 0.02"/>
    </collision>
  </link>
  <joint name="right_hand_joint" type="fixed">
    <origin rpy="0.35 0 0" xyz="0 0.058 0.03"/>
    <parent link="right_arm"/>
    <child link="right_hand"/>
  </joint>
  <link name="right_hand">
    <visual>
      <geometry>
        <mesh filename="package://marty_description/meshes/hand.stl"/>
      </geometry>
      <material name="yellow"/>
      <origin rpy="0 0 3.1415" xyz="0.013125 0.0189 -0.006"/>
    </visual>
    <collision>
      <geometry>
        <mesh filename="package://marty_description/meshes/hand.stl"/>
      </geometry>
      <material name="yellow"/>
      <origin rpy="0 0 3.1415" xyz="0.013125 0.0189 -0.006"/>
    </collision>
  </link>
  <joint name="right_eye_joint" type="revolute">
    <origin rpy="0 0 0" xyz="0.079 -0.02425 -0.0275"/>
    <mimic joint="left_eye_joint" multiplier="-1" offset="0"/>
    <axis xyz="1 0 0"/>
    <limit effort="1000.0" lower="-3.1415" upper="3.1415" velocity="0.5"/>
    <parent link="face"/>
    <child link="right_eye"/>
  </joint>
  <link name="right_eye">
    <visual>
      <geometry>
        <mesh filename="package://marty_description/meshes/eyeRight.stl"/>
      </geometry>
      <material name="white">
        <color rgba="1 1 1 1"/>
      </material>
      <origin rpy="1.57 -0.06 -1.57" xyz="0.0037 0.022 -0.025"/>
    </visual>
    <collision>
      <geometry>
        <mesh filename="package://marty_description/meshes/eyeRight.stl"/>
      </geometry>
      <material name="white">
        <color rgba="1 1 1 1"/>
      </material>
      <origin rpy="1.57 -0.06 -1.57" xyz="0.0037 0.022 -0.025"/>
    </collision>
  </link>
  <joint name="left_eye_joint" type="revolute">
    <origin rpy="0 0 0" xyz="0.079 0.02125 -0.0275"/>
    <axis xyz="1 0 0"/>
    <limit effort="1000.0" lower="-2.35" upper="0.23" velocity="0.5"/>
    <parent link="face"/>
    <child link="left_eye"/>
  </joint>
  <link name="left_eye">
    <visual>
      <geometry>
        <mesh filename="package://marty_description/meshes/eyeLeft.stl"/>
      </geometry>
      <material name="white"/>
      <origin rpy="1.57 -0.02 1.57" xyz="0 -0.023 -0.0238"/>
    </visual>
    <collision>
      <geometry>
        <mesh filename="package://marty_description/meshes/eyeLeft.stl"/>
      </geometry>
      <material name="white"/>
      <origin rpy="1.57 -0.02 1.57" xyz="0 -0.023 -0.0238"/>
    </collision>
  </link>
  <joint name="left_hip_servo_holder_joint" type="fixed">
    <origin rpy="0 0 0" xyz="-0.0075 0.01825 -0.015"/>
    <parent link="base_link"/>
    <child link="left_hip_servo_holder"/>
  </joint>
  <link name="left_hip_servo_holder">
    <visual>
      <geometry>
        <mesh filename="package://marty_description/meshes/servoHolder.stl"/>
      </geometry>
      <material name="blue"/>
      <origin rpy="1.57 0 3.1415" xyz="0.0282 -0.00825 -0.0095"/>
    </visual>
    <collision>
      <geometry>
        <mesh filename="package://marty_description/meshes/servoHolder.stl"/>
      </geometry>
      <material name="blue"/>
      <origin rpy="1.57 0 3.1415" xyz="0.0282 -0.00825 -0.0095"/>
    </collision>
  </link>
  <joint name="left_hip_servo_mount_joint" type="fixed">
    <origin rpy="0 0 0" xyz="-0.0075 0.03825 -0.015"/>
    <parent link="base_link"/>
    <child link="left_hip_servo_mount"/>
  </joint>
  <link name="left_hip_servo_mount">
    <visual>
      <geometry>
        <mesh filename="package://marty_description/meshes/servoMount.stl"/>
      </geometry>
      <material name="blue"/>
      <origin rpy="1.57 0 0" xyz="-0.0258 0.0078   -0.0095"/>
    </visual>
    <collision>
      <geometry>
        <mesh filename="package://marty_description/meshes/servoMount.stl"/>
      </geometry>
      <material name="blue"/>
      <origin rpy="1.57 0 0" xyz="-0.0258 0.0078   -0.0095"/>
    </collision>
  </link>
  <joint name="left_hip_link1_joint" type="revolute">
    <origin rpy="0 0 0" xyz="0.00925 0 0.00376"/>
    <mimic joint="left_hip_servo_link_joint" multiplier="1" offset="0"/>
    <axis xyz="0 1 0"/>
    <limit effort="1000.0" lower="-1.57" upper="1.57" velocity="0.5"/>
    <parent link="left_hip_servo_holder"/>
    <child link="left_hip_link1"/>
  </joint>
  <link name="left_hip_link1">
    <visual>
      <geometry>
        <mesh filename="package://marty_description/meshes/link.stl"/>
      </geometry>
      <material name="blue"/>
      <origin rpy="0 1.57 0" xyz="-0.003 -0.0121 0.003"/>
    </visual>
    <collision>
      <geometry>
        <mesh filename="package://marty_description/meshes/link.stl"/>
      </geometry>
      <material name="blue"/>
      <origin rpy="0 1.57 0" xyz="-0.003 -0.0121 0.003"/>
    </collision>
  </link>
  <joint name="left_hip_link2_joint" type="revolute">
    <origin rpy="0 0 0" xyz="-0.0069 0 0.00376"/>
    <mimic joint="left_hip_servo_link_joint" multiplier="1" offset="0"/>
    <axis xyz="0 1 0"/>
    <limit effort="1000.0" lower="-1.57" upper="1.57" velocity="0.5"/>
    <parent link="left_hip_servo_holder"/>
    <child link="left_hip_link2"/>
  </joint>
  <link name="left_hip_link2">
    <visual>
      <geometry>
        <mesh filename="package://marty_description/meshes/link.stl"/>
      </geometry>
      <material name="blue"/>
      <origin rpy="0 -1.57 0" xyz="0.003 -0.0121 -0.053"/>
    </visual>
    <collision>
      <geometry>
        <mesh filename="package://marty_description/meshes/link.stl"/>
      </geometry>
      <material name="blue"/>
      <origin rpy="0 -1.57 0" xyz="0.003 -0.0121 -0.053"/>
    </collision>
  </link>
  <joint name="left_hip_link3_joint" type="revolute">
    <origin rpy="0 0 0" xyz="-0.007 0 0.00376"/>
    <mimic joint="left_hip_servo_link_joint" multiplier="1" offset="0"/>
    <axis xyz="0 1 0"/>
    <limit effort="1000.0" lower="-1.57" upper="1.57" velocity="0.5"/>
    <parent link="left_hip_servo_mount"/>
    <child link="left_hip_link3"/>
  </joint>
  <link name="left_hip_link3">
    <visual>
      <geometry>
        <mesh filename="package://marty_description/meshes/link.stl"/>
      </geometry>
      <material name="blue"/>
      <origin rpy="0 1.57 3.1415" xyz="0.0031 0.0116 0.003"/>
    </visual>
    <collision>
      <geometry>
        <mesh filename="package://marty_description/meshes/link.stl"/>
      </geometry>
      <material name="blue"/>
      <origin rpy="0 1.57 3.1415" xyz="0.0031 0.0116 0.003"/>
    </collision>
  </link>
  <joint name="left_hip_servo_link_joint" type="revolute">
    <origin rpy="0 0 0" xyz="0.00925 0 0.00376"/>
    <axis xyz="0 1 0"/>
    <limit effort="1000.0" lower="-1.03" upper="1.03" velocity="0.5"/>
    <parent link="left_hip_servo_mount"/>
    <child link="left_hip_servo_link"/>
  </joint>
  <link name="left_hip_servo_link">
    <visual>
      <geometry>
        <mesh filename="package://marty_description/meshes/servoLink.stl"/>
      </geometry>
      <material name="blue"/>
      <origin rpy="0 -1.57 3.1415" xyz="-0.005 0.0116 -0.053"/>
    </visual>
    <collision>
      <geometry>
        <mesh filename="package://marty_description/meshes/servoLink.stl"/>
      </geometry>
      <material name="blue"/>
      <origin rpy="0 -1.57 3.1415" xyz="-0.005 0.0116 -0.053"/>
    </collision>
  </link>
  <joint name="left_hip_crossbrace1_joint" type="fixed">
    <origin rpy="0 0 0" xyz="0 -0.01 -0.025"/>
    <parent link="left_hip_servo_link"/>
    <child link="left_hip_crossbrace1"/>
  </joint>
  <link name="left_hip_crossbrace1">
    <visual>
      <geometry>
        <mesh filename="package://marty_description/meshes/crossbrace.stl"/>
      </geometry>
      <material name="yellow"/>
      <origin rpy="1.57 0 1.57" xyz="0.0031 -0.0204 -0.0125"/>
    </visual>
    <collision>
      <geometry>
        <mesh filename="package://marty_description/meshes/crossbrace.stl"/>
      </geometry>
      <material name="yellow"/>
      <origin rpy="1.57 0 1.57" xyz="0.0031 -0.0204 -0.0125"/>
    </collision>
  </link>
  <joint name="left_hip_crossbrace2_joint" type="fixed">
    <origin rpy="0 0 0" xyz="0 -0.01 -0.025"/>
    <parent link="left_hip_link3"/>
    <child link="left_hip_crossbrace2"/>
  </joint>
  <link name="left_hip_crossbrace2">
    <visual>
      <geometry>
        <mesh filename="package://marty_description/meshes/crossbrace.stl"/>
      </geometry>
      <material name="yellow"/>
      <origin rpy="1.57 0 -1.57" xyz="-0.0031 0.0199 -0.0125"/>
    </visual>
    <collision>
      <geometry>
        <mesh filename="package://marty_description/meshes/crossbrace.stl"/>
      </geometry>
      <material name="yellow"/>
      <origin rpy="1.57 0 -1.57" xyz="-0.0031 0.0199 -0.0125"/>
    </collision>
  </link>
  <joint name="left_twist_servo_holder1_joint" type="revolute">
    <origin rpy="0 0 0" xyz="0 0 -0.05"/>
    <axis xyz="0 1 0"/>
    <limit effort="1000.0" lower="-1.57" upper="1.57" velocity="0.5"/>
    <mimic joint="left_hip_servo_link_joint" multiplier="-1" offset="0"/>
    <parent link="left_hip_servo_link"/>
    <child link="left_twist_servo_holder1"/>
  </joint>
  <link name="left_twist_servo_holder1">
    <visual>
      <geometry>
        <mesh filename="package://marty_description/meshes/servoHolder.stl"/>
      </geometry>
      <material name="blue"/>
      <origin rpy="1.57 3.1415 0" xyz="0.0188 0.00785 0.013"/>
    </visual>
    <collision>
      <geometry>
        <mesh filename="package://marty_description/meshes/servoHolder.stl"/>
      </geometry>
      <material name="blue"/>
      <origin rpy="1.57 3.1415 0" xyz="0.0188 0.00785 0.013"/>
    </collision>
  </link>
  <joint name="left_twist_servo_holder2_joint" type="fixed">
    <origin rpy="0 0 0" xyz="0 -0.02 0"/>
    <parent link="left_twist_servo_holder1"/>
    <child link="left_twist_servo_holder2"/>
  </joint>
  <link name="left_twist_servo_holder2">
    <visual>
      <geometry>
        <mesh filename="package://marty_description/meshes/servoHolder.stl"/>
      </geometry>
      <material name="blue"/>
      <origin rpy="-1.57 0 0" xyz="-0.035225 -0.00825 0.013"/>
    </visual>
    <collision>
      <geometry>
        <mesh filename="package://marty_description/meshes/servoHolder.stl"/>
      </geometry>
      <material name="blue"/>
      <origin rpy="-1.57 0 0" xyz="-0.035225 -0.00825 0.013"/>
    </collision>
  </link>
  <joint name="left_twist_shaft_joint" type="revolute">
    <origin rpy="0 0 0" xyz="-0.009 -0.01 -0.0164"/>
    <axis xyz="0 0 1"/>
    <limit effort="1000.0" lower="-1.57" upper="1.57" velocity="0.5"/>
    <parent link="left_twist_servo_holder1"/>
    <child link="left_twist_shaft"/>
  </joint>
  <link name="left_twist_shaft">
    <visual>
      <geometry>
        <mesh filename="package://marty_description/meshes/twistShaft.stl"/>
      </geometry>
      <material name="orange">
        <color rgba="0.84 0.41 0.14 1"/>
      </material>
      <origin rpy="1.57 0 -1.57" xyz="0.01635 0.01325 0"/>
    </visual>
    <collision>
      <geometry>
        <mesh filename="package://marty_description/meshes/twistShaft.stl"/>
      </geometry>
      <material name="orange">
        <color rgba="0.84 0.41 0.14 1"/>
      </material>
      <origin rpy="1.57 0 -1.57" xyz="0.01635 0.01325 0"/>
    </collision>
  </link>
  <joint name="left_knee_servo_holder_joint" type="fixed">
    <origin rpy="0 0 0" xyz="0.01 0.008 -0.0062"/>
    <parent link="left_twist_shaft"/>
    <child link="left_knee_servo_holder"/>
  </joint>
  <link name="left_knee_servo_holder">
    <visual>
      <geometry>
        <mesh filename="package://marty_description/meshes/servoHolder.stl"/>
      </geometry>
      <material name="blue"/>
      <origin rpy="1.57 0 -1.57" xyz="0.00855 0.01885 -0.0133"/>
    </visual>
    <collision>
      <geometry>
        <mesh filename="package://marty_description/meshes/servoHolder.stl"/>
      </geometry>
      <material name="blue"/>
      <origin rpy="1.57 0 -1.57" xyz="0.00855 0.01885 -0.0133"/>
    </collision>
  </link>
  <joint name="left_knee_servo_mount_joint" type="fixed">
    <origin rpy="0 0 0" xyz="-0.0099 0.008 -0.0062"/>
    <parent link="left_twist_shaft"/>
    <child link="left_knee_servo_mount"/>
  </joint>
  <link name="left_knee_servo_mount">
    <visual>
      <geometry>
        <mesh filename="package://marty_description/meshes/servoMount.stl"/>
      </geometry>
      <material name="blue"/>
      <origin rpy="1.57 0 1.57" xyz="-0.0075825 -0.0351 -0.0133"/>
    </visual>
    <collision>
      <geometry>
        <mesh filename="package://marty_description/meshes/servoMount.stl"/>
      </geometry>
      <material name="blue"/>
      <origin rpy="1.57 0 1.57" xyz="-0.0075825 -0.0351 -0.0133"/>
    </collision>
  </link>
  <joint name="left_knee_link1_joint" type="revolute">
    <origin rpy="0 0 0" xyz="0 0 0"/>
    <mimic joint="left_knee_servo_link_joint" multiplier="1" offset="0"/>
    <axis xyz="1 0 0"/>
    <limit effort="1000.0" lower="-1.57" upper="1.57" velocity="0.5"/>
    <parent link="left_knee_servo_holder"/>
    <child link="left_knee_link1"/>
  </joint>
  <link name="left_knee_link1">
    <visual>
      <geometry>
        <mesh filename="package://marty_description/meshes/link.stl"/>
      </geometry>
      <material name="blue"/>
      <origin rpy="0 1.57 1.57" xyz="0.0123 -0.003 0.003"/>
    </visual>
    <collision>
      <geometry>
        <mesh filename="package://marty_description/meshes/link.stl"/>
      </geometry>
      <material name="blue"/>
      <origin rpy="0 1.57 1.57" xyz="0.0123 -0.003 0.003"/>
    </collision>
  </link>
  <joint name="left_knee_link2_joint" type="revolute">
    <origin rpy="0 0 0" xyz="0 -0.01615 0"/>
    <mimic joint="left_knee_servo_link_joint" multiplier="1" offset="0"/>
    <axis xyz="1 0 0"/>
    <limit effort="1000.0" lower="-1.57" upper="1.57" velocity="0.5"/>
    <parent link="left_knee_servo_holder"/>
    <child link="left_knee_link2"/>
  </joint>
  <link name="left_knee_link2">
    <visual>
      <geometry>
        <mesh filename="package://marty_description/meshes/link.stl"/>
      </geometry>
      <material name="blue"/>
      <origin rpy="0 -1.57 1.57" xyz="0.0123 0.00291 -0.053"/>
    </visual>
    <collision>
      <geometry>
        <mesh filename="package://marty_description/meshes/link.stl"/>
      </geometry>
      <material name="blue"/>
      <origin rpy="0 -1.57 1.57" xyz="0.0123 0.00291 -0.053"/>
    </collision>
  </link>
  <joint name="left_knee_link3_joint" type="revolute">
    <origin rpy="0 0 0" xyz="-0.005 -0.01615 0"/>
    <mimic joint="left_knee_servo_link_joint" multiplier="1" offset="0"/>
    <axis xyz="1 0 0"/>
    <limit effort="1000.0" lower="-1.57" upper="1.57" velocity="0.5"/>
    <parent link="left_knee_servo_mount"/>
    <child link="left_knee_link3"/>
  </joint>
  <link name="left_knee_link3">
    <visual>
      <geometry>
        <mesh filename="package://marty_description/meshes/link.stl"/>
      </geometry>
      <material name="blue"/>
      <origin rpy="0 1.57 -1.57" xyz="-0.0064 0.00291 0.003"/>
    </visual>
    <collision>
      <geometry>
        <mesh filename="package://marty_description/meshes/link.stl"/>
      </geometry>
      <material name="blue"/>
      <origin rpy="0 1.57 -1.57" xyz="-0.0064 0.00291 0.003"/>
    </collision>
  </link>
  <joint name="left_knee_servo_link_joint" type="revolute">
    <origin rpy="0 0 0" xyz="-0.005 0 0"/>
    <axis xyz="1 0 0"/>
    <limit effort="1000.0" lower="-1.03" upper="1.03" velocity="0.5"/>
    <parent link="left_knee_servo_mount"/>
    <child link="left_knee_servo_link"/>
  </joint>
  <link name="left_knee_servo_link">
    <visual>
      <geometry>
        <mesh filename="package://marty_description/meshes/servoLink.stl"/>
      </geometry>
      <material name="blue"/>
      <origin rpy="0 -1.57 -1.57" xyz="-0.0064 -0.005 -0.053"/>
    </visual>
    <collision>
      <geometry>
        <mesh filename="package://marty_description/meshes/servoLink.stl"/>
      </geometry>
      <material name="blue"/>
      <origin rpy="0 -1.57 -1.57" xyz="-0.0064 -0.005 -0.053"/>
    </collision>
  </link>
  <joint name="left_knee_crossbrace1_joint" type="fixed">
    <origin rpy="0 0 0" xyz="0.015 0.01 -0.025"/>
    <parent link="left_knee_servo_link"/>
    <child link="left_knee_crossbrace1"/>
  </joint>
  <link name="left_knee_crossbrace1">
    <visual>
      <geometry>
        <mesh filename="package://marty_description/meshes/crossbrace.stl"/>
      </geometry>
      <material name="yellow"/>
      <origin rpy="1.57 0 -3.1415" xyz="0.02075 -0.0067 -0.0125"/>
    </visual>
    <collision>
      <geometry>
        <mesh filename="package://marty_description/meshes/crossbrace.stl"/>
      </geometry>
      <material name="yellow"/>
      <origin rpy="1.57 0 -3.1415" xyz="0.02075 -0.0067 -0.0125"/>
    </collision>
  </link>
  <joint name="left_knee_crossbrace2_joint" type="fixed">
    <origin rpy="0 0 0" xyz="0.015 -0.01 -0.025"/>
    <parent link="left_knee_link3"/>
    <child link="left_knee_crossbrace2"/>
  </joint>
  <link name="left_knee_crossbrace2">
    <visual>
      <geometry>
        <mesh filename="package://marty_description/meshes/crossbrace.stl"/>
      </geometry>
      <material name="yellow"/>
      <origin rpy="1.57 0 0" xyz="-0.01925 0.0067 -0.0125"/>
    </visual>
    <collision>
      <geometry>
        <mesh filename="package://marty_description/meshes/crossbrace.stl"/>
      </geometry>
      <material name="yellow"/>
      <origin rpy="1.57 0 0" xyz="-0.01925 0.0067 -0.0125"/>
    </collision>
  </link>
  <joint name="left_foot_joint" type="revolute">
    <origin rpy="0 0 0" xyz="0 0 -0.05"/>
    <mimic joint="left_knee_servo_link_joint" multiplier="-1" offset="0"/>
    <axis xyz="1 0 0"/>
    <limit effort="1000.0" lower="-1.03" upper="1.03" velocity="0.5"/>
    <parent link="left_knee_servo_link"/>
    <child link="left_foot"/>
  </joint>
  <link name="left_foot">
    <visual>
      <geometry>
        <mesh filename="package://marty_description/meshes/foot.stl"/>
      </geometry>
      <material name="blue"/>
      <origin rpy="1.57 0 3.1415" xyz="0.0635 -0.0306 -0.00725"/>
    </visual>
    <collision>
      <geometry>
        <mesh filename="package://marty_description/meshes/foot.stl"/>
      </geometry>
      <material name="blue"/>
      <origin rpy="1.57 0 3.1415" xyz="0.0635 -0.0306 -0.00725"/>
    </collision>
  </link>
  <joint name="right_hip_servo_holder_joint" type="fixed">
    <origin rpy="0 0 0" xyz="-0.0075 -0.03825 -0.015"/>
    <parent link="base_link"/>
    <child link="right_hip_servo_holder"/>
  </joint>
  <link name="right_hip_servo_holder">
    <visual>
      <geometry>
        <mesh filename="package://marty_description/meshes/servoHolder.stl"/>
      </geometry>
      <material name="blue"/>
      <origin rpy="1.57 0 3.1415" xyz="0.0282 -0.00825 -0.0095"/>
    </visual>
    <collision>
      <geometry>
        <mesh filename="package://marty_description/meshes/servoHolder.stl"/>
      </geometry>
      <material name="blue"/>
      <origin rpy="1.57 0 3.1415" xyz="0.0282 -0.00825 -0.0095"/>
    </collision>
  </link>
  <joint name="right_hip_servo_mount_joint" type="fixed">
    <origin rpy="0 0 0" xyz="-0.0075 -0.01825 -0.015"/>
    <parent link="base_link"/>
    <child link="right_hip_servo_mount"/>
  </joint>
  <link name="right_hip_servo_mount">
    <visual>
      <geometry>
        <mesh filename="package://marty_description/meshes/servoMount.stl"/>
      </geometry>
      <material name="blue"/>
      <origin rpy="1.57 0 0" xyz="-0.0258 0.0078   -0.0095"/>
    </visual>
    <collision>
      <geometry>
        <mesh filename="package://marty_description/meshes/servoMount.stl"/>
      </geometry>
      <material name="blue"/>
      <origin rpy="1.57 0 0" xyz="-0.0258 0.0078   -0.0095"/>
    </collision>
  </link>
  <joint name="right_hip_link1_joint" type="revolute">
    <origin rpy="0 0 0" xyz="0.00925 0 0.00376"/>
    <mimic joint="right_hip_servo_link_joint" multiplier="1" offset="0"/>
    <axis xyz="0 1 0"/>
    <limit effort="1000.0" lower="-1.57" upper="1.57" velocity="0.5"/>
    <parent link="right_hip_servo_holder"/>
    <child link="right_hip_link1"/>
  </joint>
  <link name="right_hip_link1">
    <visual>
      <geometry>
        <mesh filename="package://marty_description/meshes/link.stl"/>
      </geometry>
      <material name="blue"/>
      <origin rpy="0 1.57 0" xyz="-0.003 -0.0121 0.003"/>
    </visual>
    <collision>
      <geometry>
        <mesh filename="package://marty_description/meshes/link.stl"/>
      </geometry>
      <material name="blue"/>
      <origin rpy="0 1.57 0" xyz="-0.003 -0.0121 0.003"/>
    </collision>
  </link>
  <joint name="right_hip_link2_joint" type="revolute">
    <origin rpy="0 0 0" xyz="-0.0069 0 0.00376"/>
    <mimic joint="right_hip_servo_link_joint" multiplier="1" offset="0"/>
    <axis xyz="0 1 0"/>
    <limit effort="1000.0" lower="-1.57" upper="1.57" velocity="0.5"/>
    <parent link="right_hip_servo_holder"/>
    <child link="right_hip_link2"/>
  </joint>
  <link name="right_hip_link2">
    <visual>
      <geometry>
        <mesh filename="package://marty_description/meshes/link.stl"/>
      </geometry>
      <material name="blue"/>
      <origin rpy="0 -1.57 0" xyz="0.003 -0.0121 -0.053"/>
    </visual>
    <collision>
      <geometry>
        <mesh filename="package://marty_description/meshes/link.stl"/>
      </geometry>
      <material name="blue"/>
      <origin rpy="0 -1.57 0" xyz="0.003 -0.0121 -0.053"/>
    </collision>
  </link>
  <joint name="right_hip_link3_joint" type="revolute">
    <origin rpy="0 0 0" xyz="-0.007 0 0.00376"/>
    <mimic joint="right_hip_servo_link_joint" multiplier="1" offset="0"/>
    <axis xyz="0 1 0"/>
    <limit effort="1000.0" lower="-1.57" upper="1.57" velocity="0.5"/>
    <parent link="right_hip_servo_mount"/>
    <child link="right_hip_link3"/>
  </joint>
  <link name="right_hip_link3">
    <visual>
      <geometry>
        <mesh filename="package://marty_description/meshes/link.stl"/>
      </geometry>
      <material name="blue"/>
      <origin rpy="0 1.57 3.1415" xyz="0.0031 0.0116 0.003"/>
    </visual>
    <collision>
      <geometry>
        <mesh filename="package://marty_description/meshes/link.stl"/>
      </geometry>
      <material name="blue"/>
      <origin rpy="0 1.57 3.1415" xyz="0.0031 0.0116 0.003"/>
    </collision>
  </link>
  <joint name="right_hip_servo_link_joint" type="revolute">
    <origin rpy="0 0 0" xyz="0.00925 0 0.00376"/>
    <axis xyz="0 1 0"/>
    <limit effort="1000.0" lower="-1.03" upper="1.03" velocity="0.5"/>
    <parent link="right_hip_servo_mount"/>
    <child link="right_hip_servo_link"/>
  </joint>
  <link name="right_hip_servo_link">
    <visual>
      <geometry>
        <mesh filename="package://marty_description/meshes/servoLink.stl"/>
      </geometry>
      <material name="blue"/>
      <origin rpy="0 -1.57 3.1415" xyz="-0.005 0.0116 -0.053"/>
    </visual>
    <collision>
      <geometry>
        <mesh filename="package://marty_description/meshes/servoLink.stl"/>
      </geometry>
      <material name="blue"/>
      <origin rpy="0 -1.57 3.1415" xyz="-0.005 0.0116 -0.053"/>
    </collision>
  </link>
  <joint name="right_hip_crossbrace1_joint" type="fixed">
    <origin rpy="0 0 0" xyz="0 -0.01 -0.025"/>
    <parent link="right_hip_servo_link"/>
    <child link="right_hip_crossbrace1"/>
  </joint>
  <link name="right_hip_crossbrace1">
    <visual>
      <geometry>
        <mesh filename="package://marty_description/meshes/crossbrace.stl"/>
      </geometry>
      <material name="yellow"/>
      <origin rpy="1.57 0 1.57" xyz="0.0031 -0.0204 -0.0125"/>
    </visual>
    <collision>
      <geometry>
        <mesh filename="package://marty_description/meshes/crossbrace.stl"/>
      </geometry>
      <material name="yellow"/>
      <origin rpy="1.57 0 1.57" xyz="0.0031 -0.0204 -0.0125"/>
    </collision>
  </link>
  <joint name="right_hip_crossbrace2_joint" type="fixed">
    <origin rpy="0 0 0" xyz="0 -0.01 -0.025"/>
    <parent link="right_hip_link3"/>
    <child link="right_hip_crossbrace2"/>
  </joint>
  <link name="right_hip_crossbrace2">
    <visual>
      <geometry>
        <mesh filename="package://marty_description/meshes/crossbrace.stl"/>
      </geometry>
      <material name="yellow"/>
      <origin rpy="1.57 0 -1.57" xyz="-0.0031 0.0199 -0.0125"/>
    </visual>
    <collision>
      <geometry>
        <mesh filename="package://marty_description/meshes/crossbrace.stl"/>
      </geometry>
      <material name="yellow"/>
      <origin rpy="1.57 0 -1.57" xyz="-0.0031 0.0199 -0.0125"/>
    </collision>
  </link>
  <joint name="right_twist_servo_holder1_joint" type="revolute">
    <origin rpy="0 0 0" xyz="0 0 -0.05"/>
    <axis xyz="0 1 0"/>
    <limit effort="1000.0" lower="-1.57" upper="1.57" velocity="0.5"/>
    <mimic joint="right_hip_servo_link_joint" multiplier="-1" offset="0"/>
    <parent link="right_hip_servo_link"/>
    <child link="right_twist_servo_holder1"/>
  </joint>
  <link name="right_twist_servo_holder1">
    <visual>
      <geometry>
        <mesh filename="package://marty_description/meshes/servoHolder.stl"/>
      </geometry>
      <material name="blue"/>
      <origin rpy="1.57 3.1415 0" xyz="0.0188 0.00785 0.013"/>
    </visual>
    <collision>
      <geometry>
        <mesh filename="package://marty_description/meshes/servoHolder.stl"/>
      </geometry>
      <material name="blue"/>
      <origin rpy="1.57 3.1415 0" xyz="0.0188 0.00785 0.013"/>
    </collision>
  </link>
  <joint name="right_twist_servo_holder2_joint" type="fixed">
    <origin rpy="0 0 0" xyz="0 -0.02 0"/>
    <parent link="right_twist_servo_holder1"/>
    <child link="right_twist_servo_holder2"/>
  </joint>
  <link name="right_twist_servo_holder2">
    <visual>
      <geometry>
        <mesh filename="package://marty_description/meshes/servoHolder.stl"/>
      </geometry>
      <material name="blue"/>
      <origin rpy="-1.57 0 0" xyz="-0.035225 -0.00825 0.013"/>
    </visual>
    <collision>
      <geometry>
        <mesh filename="package://marty_description/meshes/servoHolder.stl"/>
      </geometry>
      <material name="blue"/>
      <origin rpy="-1.57 0 0" xyz="-0.035225 -0.00825 0.013"/>
    </collision>
  </link>
  <joint name="right_twist_shaft_joint" type="revolute">
    <origin rpy="0 0 0" xyz="-0.009 -0.01 -0.0164"/>
    <axis xyz="0 0 1"/>
    <limit effort="1000.0" lower="-1.57" upper="1.57" velocity="0.5"/>
    <parent link="right_twist_servo_holder1"/>
    <child link="right_twist_shaft"/>
  </joint>
  <link name="right_twist_shaft">
    <visual>
      <geometry>
        <mesh filename="package://marty_description/meshes/twistShaft.stl"/>
      </geometry>
      <material name="orange">
        <color rgba="0.84 0.41 0.14 1"/>
      </material>
      <origin rpy="1.57 0 -1.57" xyz="0.01635 0.01325 0"/>
    </visual>
    <collision>
      <geometry>
        <mesh filename="package://marty_description/meshes/twistShaft.stl"/>
      </geometry>
      <material name="orange">
        <color rgba="0.84 0.41 0.14 1"/>
      </material>
      <origin rpy="1.57 0 -1.57" xyz="0.01635 0.01325 0"/>
    </collision>
  </link>
  <joint name="right_knee_servo_holder_joint" type="fixed">
    <origin rpy="0 0 0" xyz="0.01 0.008 -0.0062"/>
    <parent link="right_twist_shaft"/>
    <child link="right_knee_servo_holder"/>
  </joint>
  <link name="right_knee_servo_holder">
    <visual>
      <geometry>
        <mesh filename="package://marty_description/meshes/servoHolder.stl"/>
      </geometry>
      <material name="blue"/>
      <origin rpy="1.57 0 -1.57" xyz="0.00855 0.01885 -0.0133"/>
    </visual>
    <collision>
      <geometry>
        <mesh filename="package://marty_description/meshes/servoHolder.stl"/>
      </geometry>
      <material name="blue"/>
      <origin rpy="1.57 0 -1.57" xyz="0.00855 0.01885 -0.0133"/>
    </collision>
  </link>
  <joint name="right_knee_servo_mount_joint" type="fixed">
    <origin rpy="0 0 0" xyz="-0.0099 0.008 -0.0062"/>
    <parent link="right_twist_shaft"/>
    <child link="right_knee_servo_mount"/>
  </joint>
  <link name="right_knee_servo_mount">
    <visual>
      <geometry>
        <mesh filename="package://marty_description/meshes/servoMount.stl"/>
      </geometry>
      <material name="blue"/>
      <origin rpy="1.57 0 1.57" xyz="-0.0075825 -0.0351 -0.0133"/>
    </visual>
    <collision>
      <geometry>
        <mesh filename="package://marty_description/meshes/servoMount.stl"/>
      </geometry>
      <material name="blue"/>
      <origin rpy="1.57 0 1.57" xyz="-0.0075825 -0.0351 -0.0133"/>
    </collision>
  </link>
  <joint name="right_knee_link1_joint" type="revolute">
    <origin rpy="0 0 0" xyz="0 0 0"/>
    <mimic joint="right_knee_servo_link_joint" multiplier="1" offset="0"/>
    <axis xyz="1 0 0"/>
    <limit effort="1000.0" lower="-1.57" upper="1.57" velocity="0.5"/>
    <parent link="right_knee_servo_holder"/>
    <child link="right_knee_link1"/>
  </joint>
  <link name="right_knee_link1">
    <visual>
      <geometry>
        <mesh filename="package://marty_description/meshes/link.stl"/>
      </geometry>
      <material name="blue"/>
      <origin rpy="0 1.57 1.57" xyz="0.0123 -0.003 0.003"/>
    </visual>
    <collision>
      <geometry>
        <mesh filename="package://marty_description/meshes/link.stl"/>
      </geometry>
      <material name="blue"/>
      <origin rpy="0 1.57 1.57" xyz="0.0123 -0.003 0.003"/>
    </collision>
  </link>
  <joint name="right_knee_link2_joint" type="revolute">
    <origin rpy="0 0 0" xyz="0 -0.01615 0"/>
    <mimic joint="right_knee_servo_link_joint" multiplier="1" offset="0"/>
    <axis xyz="1 0 0"/>
    <limit effort="1000.0" lower="-1.57" upper="1.57" velocity="0.5"/>
    <parent link="right_knee_servo_holder"/>
    <child link="right_knee_link2"/>
  </joint>
  <link name="right_knee_link2">
    <visual>
      <geometry>
        <mesh filename="package://marty_description/meshes/link.stl"/>
      </geometry>
      <material name="blue"/>
      <origin rpy="0 -1.57 1.57" xyz="0.0123 0.00291 -0.053"/>
    </visual>
    <collision>
      <geometry>
        <mesh filename="package://marty_description/meshes/link.stl"/>
      </geometry>
      <material name="blue"/>
      <origin rpy="0 -1.57 1.57" xyz="0.0123 0.00291 -0.053"/>
    </collision>
  </link>
  <joint name="right_knee_link3_joint" type="revolute">
    <origin rpy="0 0 0" xyz="-0.005 -0.01615 0"/>
    <mimic joint="right_knee_servo_link_joint" multiplier="1" offset="0"/>
    <axis xyz="1 0 0"/>
    <limit effort="1000.0" lower="-1.57" upper="1.57" velocity="0.5"/>
    <parent link="right_knee_servo_mount"/>
    <child link="right_knee_link3"/>
  </joint>
  <link name="right_knee_link3">
    <visual>
      <geometry>
        <mesh filename="package://marty_description/meshes/link.stl"/>
      </geometry>
      <material name="blue"/>
      <origin rpy="0 1.57 -1.57" xyz="-0.0064 0.00291 0.003"/>
    </visual>
    <collision>
      <geometry>
        <mesh filename="package://marty_description/meshes/link.stl"/>
      </geometry>
      <material name="blue"/>
      <origin rpy="0 1.57 -1.57" xyz="-0.0064 0.00291 0.003"/>
    </collision>
  </link>
  <joint name="right_knee_servo_link_joint" type="revolute">
    <origin rpy="0 0 0" xyz="-0.005 0 0"/>
    <axis xyz="1 0 0"/>
    <limit effort="1000.0" lower="-1.03" upper="1.03" velocity="0.5"/>
    <parent link="right_knee_servo_mount"/>
    <child link="right_knee_servo_link"/>
  </joint>
  <link name="right_knee_servo_link">
    <visual>
      <geometry>
        <mesh filename="package://marty_description/meshes/servoLink.stl"/>
      </geometry>
      <material name="blue"/>
      <origin rpy="0 -1.57 -1.57" xyz="-0.0064 -0.005 -0.053"/>
    </visual>
    <collision>
      <geometry>
        <mesh filename="package://marty_description/meshes/servoLink.stl"/>
      </geometry>
      <material name="blue"/>
      <origin rpy="0 -1.57 -1.57" xyz="-0.0064 -0.005 -0.053"/>
    </collision>
  </link>
  <joint name="right_knee_crossbrace1_joint" type="fixed">
    <origin rpy="0 0 0" xyz="0.015 0.01 -0.025"/>
    <parent link="right_knee_servo_link"/>
    <child link="right_knee_crossbrace1"/>
  </joint>
  <link name="right_knee_crossbrace1">
    <visual>
      <geometry>
        <mesh filename="package://marty_description/meshes/crossbrace.stl"/>
      </geometry>
      <material name="yellow"/>
      <origin rpy="1.57 0 -3.1415" xyz="0.02075 -0.0067 -0.0125"/>
    </visual>
    <collision>
      <geometry>
        <mesh filename="package://marty_description/meshes/crossbrace.stl"/>
      </geometry>
      <material name="yellow"/>
      <origin rpy="1.57 0 -3.1415" xyz="0.02075 -0.0067 -0.0125"/>
    </collision>
  </link>
  <joint name="right_knee_crossbrace2_joint" type="fixed">
    <origin rpy="0 0 0" xyz="0.015 -0.01 -0.025"/>
    <parent link="right_knee_link3"/>
    <child link="right_knee_crossbrace2"/>
  </joint>
  <link name="right_knee_crossbrace2">
    <visual>
      <geometry>
        <mesh filename="package://marty_description/meshes/crossbrace.stl"/>
      </geometry>
      <material name="yellow"/>
      <origin rpy="1.57 0 0" xyz="-0.01925 0.0067 -0.0125"/>
    </visual>
    <collision>
      <geometry>
        <mesh filename="package://marty_description/meshes/crossbrace.stl"/>
      </geometry>
      <material name="yellow"/>
      <origin rpy="1.57 0 0" xyz="-0.01925 0.0067 -0.0125"/>
    </collision>
  </link>
  <joint name="right_foot_joint" type="revolute">
    <origin rpy="0 0 0" xyz="0 0 -0.05"/>
    <mimic joint="right_knee_servo_link_joint" multiplier="-1" offset="0"/>
    <axis xyz="1 0 0"/>
    <limit effort="1000.0" lower="-1.03" upper="1.03" velocity="0.5"/>
    <parent link="right_knee_servo_link"/>
    <child link="right_foot"/>
  </joint>
  <link name="right_foot">
    <visual>
      <geometry>
        <mesh filename="package://marty_description/meshes/foot.stl"/>
      </geometry>
      <material name="blue"/>
      <origin rpy="1.57 0 0" xyz="-0.03225 0.0143 -0.00725"/>
    </visual>
    <collision>
      <geometry>
        <mesh filename="package://marty_description/meshes/foot.stl"/>
      </geometry>
      <material name="blue"/>
      <origin rpy="1.57 0 0" xyz="-0.03225 0.0143 -0.00725"/>
    </collision>
  </link>
</robot>